{
  "comments": [
    {
      "unresolved": false,
      "key": {
        "uuid": "fea9f7e6_8fdbc646",
        "filename": "/PATCHSET_LEVEL",
        "patchSetId": 1
      },
      "lineNbr": 0,
      "author": {
        "id": 192
      },
      "writtenOn": "2021-06-23T00:01:11Z",
      "side": 1,
      "message": "Tested here: https://jenkins.edgexfoundry.org/sandbox/view/All/job/sample-service-test/job/master/4/console\nI did a replay and gave the script a bad path to ensure it would fail. Job still completed and shows success, which is what we\u0027re looking for.\n\nBuild 3 also shows a run without the forced failure, where the script still runs as intended.",
      "revId": "958cd7e315bbc9ba310183e4d590ee91b14940ee",
      "serverId": "f2a2391d-0403-4fa5-b183-4056999a8a09"
    },
    {
      "unresolved": true,
      "key": {
        "uuid": "82eef33f_99c4eb76",
        "filename": "/PATCHSET_LEVEL",
        "patchSetId": 1
      },
      "lineNbr": 0,
      "author": {
        "id": 1
      },
      "writtenOn": "2021-06-23T11:41:10Z",
      "side": 1,
      "message": "I took a look at run 3 but it doesn\u0027t seem to have passed with job-costs having failed with the exception being printed.",
      "parentUuid": "fea9f7e6_8fdbc646",
      "revId": "958cd7e315bbc9ba310183e4d590ee91b14940ee",
      "serverId": "f2a2391d-0403-4fa5-b183-4056999a8a09"
    },
    {
      "unresolved": true,
      "key": {
        "uuid": "32131d22_25c601bc",
        "filename": "/PATCHSET_LEVEL",
        "patchSetId": 1
      },
      "lineNbr": 0,
      "author": {
        "id": 192
      },
      "writtenOn": "2021-06-23T18:26:58Z",
      "side": 1,
      "message": "I\u0027m not seeing that in the console logs for build 3. I see job-cost.sh running 3 times (as it should; once on each of the parallel nodes and then once at the end), and don\u0027t see the exception printed anywhere.",
      "parentUuid": "82eef33f_99c4eb76",
      "revId": "958cd7e315bbc9ba310183e4d590ee91b14940ee",
      "serverId": "f2a2391d-0403-4fa5-b183-4056999a8a09"
    },
    {
      "unresolved": true,
      "key": {
        "uuid": "4303ddb9_e519ea22",
        "filename": "/PATCHSET_LEVEL",
        "patchSetId": 1
      },
      "lineNbr": 0,
      "author": {
        "id": 1
      },
      "writtenOn": "2021-06-23T19:23:52Z",
      "side": 1,
      "message": "Right, but I would expect to see the exception, at least once... wouldn\u0027t you if you\u0027re properly testing it?",
      "parentUuid": "32131d22_25c601bc",
      "revId": "958cd7e315bbc9ba310183e4d590ee91b14940ee",
      "serverId": "f2a2391d-0403-4fa5-b183-4056999a8a09"
    },
    {
      "unresolved": true,
      "key": {
        "uuid": "cf8916ff_9909efd9",
        "filename": "/PATCHSET_LEVEL",
        "patchSetId": 1
      },
      "lineNbr": 0,
      "author": {
        "id": 192
      },
      "writtenOn": "2021-06-23T20:36:21Z",
      "side": 1,
      "message": "Build 4 tests that the build will pass when job-cost fails. Build 3 is a normal run, and simply shows that the change didn\u0027t break the normal functionality.",
      "parentUuid": "4303ddb9_e519ea22",
      "revId": "958cd7e315bbc9ba310183e4d590ee91b14940ee",
      "serverId": "f2a2391d-0403-4fa5-b183-4056999a8a09"
    }
  ]
}